<?xml version="1.0" encoding="utf-8"?>
<!-- This URDF was automatically created by SolidWorks to URDF Exporter! Originally created by Stephen Brawner (brawner@gmail.com) 
     Commit Version: 1.6.0-4-g7f85cfe  Build Version: 1.6.7995.38578
     For more information, please see http://wiki.ros.org/sw_urdf_exporter -->
<robot
  name="RAVEN">
  <link
    name="base_link">
    <inertial>
      <origin
        xyz="0.000053 0.0 0.025049"
        rpy="0 0 0" />
      <mass
        value="0.468898" />
      <inertia
        ixx="0.0002705"
        ixy="-5.93E-09"
        ixz="3.78634E-07"
        iyy="0.0002661"
        iyz="-8.79E-10"
        izz="0.000369" />
    </inertial>
    <visual>
      <origin
        xyz="0 0 0"
        rpy="0 0 0" />
      <geometry>
        <mesh
          filename="../meshes/base_link.STL" />
      </geometry>
      <material
        name="">
        <color
          rgba="0.752941176470588 0.752941176470588 0.752941176470588 1" />
      </material>
    </visual>
    <collision>
      <origin
        xyz="0 0 0"
        rpy="0 0 0" />
      <geometry>
        <mesh
          filename="../meshes/base_link.STL" />
      </geometry>
    </collision>
  </link>
  <link
    name="shoulder_link">
    <inertial>
      <origin
        xyz="0.000083 0.001708 0.057466"
        rpy="0 0 0" />
      <mass
        value="0.598911" />
      <inertia
        ixx="0.0006411"
        ixy="8.5834E-08"
        ixz="2.5767E-06"
        iyy="0.0007509"
        iyz="-1.2909865E-05"
        izz="0.0004326" />
    </inertial>
    <visual>
      <origin
        xyz="0 0 0"
        rpy="0 0 0" />
      <geometry>
        <mesh
          filename="../meshes/shoulder_link.STL" />
      </geometry>
      <material
        name="">
        <color
          rgba="0.752941176470588 0.752941176470588 0.752941176470588 1" />
      </material>
    </visual>
    <collision>
      <origin
        xyz="0 0 0"
        rpy="0 0 0" />
      <geometry>
        <mesh
          filename="../meshes/shoulder_link.STL" />
      </geometry>
    </collision>
  </link>
  <joint
    name="shoulder_Joint"
    type="revolute">
    <origin
      xyz="0 0 0.0504"
      rpy="0 0 0" />
    <parent
      link="base_link" />
    <child
      link="shoulder_link" />
    <axis
      xyz="0 0 1" />
    <limit
      lower="-3.14"
      upper="3.14"
      effort="0"
      velocity="0" />
  </joint>
  <link
    name="upperArm_link">
    <inertial>
      <origin
        xyz="-0.180709 -0.02605 -0.000062"
        rpy="0 0 0" />
      <mass
        value="0.718905" />
      <inertia
        ixx="0.0003746"
        ixy="1.9472931E-05"
        ixz="-1.142413E-06"
        iyy="0.003941"
        iyz="1.858E-09"
        izz="0.003894" />
    </inertial>
    <visual>
      <origin
        xyz="0 0 0"
        rpy="0 0 0" />
      <geometry>
        <mesh
          filename="../meshes/upperArm_link.STL" />
      </geometry>
      <material
        name="">
        <color
          rgba="0.752941176470588 0.752941176470588 0.752941176470588 1" />
      </material>
    </visual>
    <collision>
      <origin
        xyz="0 0 0"
        rpy="0 0 0" />
      <geometry>
        <mesh
          filename="../meshes/upperArm_link.STL" />
      </geometry>
    </collision>
  </link>
  <joint
    name="upperArm_Joint"
    type="revolute">
    <origin
      xyz="0 0.027 0.07"
      rpy="0 0 0" />
    <parent
      link="shoulder_link" />
    <child
      link="upperArm_link" />
    <axis
      xyz="0 1 0" />
    <limit
      lower="0"
      upper="3.14"
      effort="0"
      velocity="0" />
  </joint>
  <link
    name="foreArm_link">
    <inertial>
      <origin
        xyz="0.065872 -0.02672 0.051838"
        rpy="0 0 0" />
      <mass
        value="0.14102" />
      <inertia
        ixx="0.0001052"
        ixy="2.527305E-06"
        ixz="-8.5217478E-05"
        iyy="0.00099"
        iyz="2.026683E-06"
        izz="0.0009641" />
    </inertial>
    <visual>
      <origin
        xyz="0 0 0"
        rpy="0 0 0" />
      <geometry>
        <mesh
          filename="../meshes/foreArm_link.STL" />
      </geometry>
      <material
        name="">
        <color
          rgba="0.752941176470588 0.752941176470588 0.752941176470588 1" />
      </material>
    </visual>
    <collision>
      <origin
        xyz="0 0 0"
        rpy="0 0 0" />
      <geometry>
        <mesh
          filename="../meshes/foreArm_link.STL" />
      </geometry>
    </collision>
  </link>
  <joint
    name="foreArm_Joint"
    type="revolute">
    <origin
      xyz="-0.225 -2.5E-05 -7.5E-05"
      rpy="0 0 0" />
    <parent
      link="upperArm_link" />
    <child
      link="foreArm_link" />
    <axis
      xyz="0 -1 0" />
    <limit
      lower="0"
      upper="3.14"
      effort="0"
      velocity="0" />
  </joint>
</robot>