<?xml version="1.0" encoding="utf-8"?>
<!-- This URDF was automatically created by SolidWorks to URDF Exporter! Originally created by Stephen Brawner (brawner@gmail.com) 
     Commit Version: 1.6.0-4-g7f85cfe  Build Version: 1.6.7995.38578
     For more information, please see http://wiki.ros.org/sw_urdf_exporter -->
<robot
  name="RAVEN_assembly2">
  <link
    name="base_link">
    <inertial>
      <origin
        xyz="0.0001453 -7.3232E-07 0.02219"
        rpy="0 0 0" />
      <mass
        value="0.24946" />
      <inertia
        ixx="0.00014181"
        ixy="6.28E-09"
        ixz="-2.6684E-07"
        iyy="0.00013613"
        iyz="1.232E-09"
        izz="0.00022186" />
    </inertial>
    <visual>
      <origin
        xyz="0 0 0"
        rpy="0 0 0" />
      <geometry>
        <mesh
          filename="../meshes/base_link.STL" />
      </geometry>
      <material
        name="">
        <color
          rgba="0.75294 0.75294 0.75294 1" />
      </material>
    </visual>
    <collision>
      <origin
        xyz="0 0 0"
        rpy="0 0 0" />
      <geometry>
        <mesh
          filename="../meshes/base_link.STL" />
      </geometry>
    </collision>
  </link>
  <link
    name="shoulder_link">
    <inertial>
      <origin
        xyz="0.00016748 -0.00027507 -0.023903"
        rpy="0 0 0" />
      <mass
        value="0.4346" />
      <inertia
        ixx="0.00030527"
        ixy="-2.0494E-07"
        ixz="1.6194E-07"
        iyy="0.00038654"
        iyz="2.4834E-05"
        izz="0.00039063" />
    </inertial>
    <visual>
      <origin
        xyz="0 0 0"
        rpy="0 0 0" />
      <geometry>
        <mesh
          filename="../meshes/shoulder_link.STL" />
      </geometry>
      <material
        name="">
        <color
          rgba="0.75294 0.75294 0.75294 1" />
      </material>
    </visual>
    <collision>
      <origin
        xyz="0 0 0"
        rpy="0 0 0" />
      <geometry>
        <mesh
          filename="../meshes/shoulder_link.STL" />
      </geometry>
    </collision>
  </link>
  <joint
    name="shoulder_yaw"
    type="revolute">
    <origin
      xyz="0 0 0.120500000000001"
      rpy="0 0 0" />
    <parent
      link="base_link" />
    <child
      link="shoulder_link" />
    <axis
      xyz="0 0 -1" />
    <limit
      lower="-3.14"
      upper="3.14"
      effort="0"
      velocity="0" />
  </joint>
  <link
    name="upperArm_link">
    <inertial>
      <origin
        xyz="-0.16504 5.8627E-05 3.2792E-08"
        rpy="0 0 0" />
      <mass
        value="0.38582" />
      <inertia
        ixx="0.00023885"
        ixy="-2.5477E-05"
        ixz="3.1366E-10"
        iyy="0.00037973"
        iyz="1.5474E-10"
        izz="0.00037655" />
    </inertial>
    <visual>
      <origin
        xyz="0 0 0"
        rpy="0 0 0" />
      <geometry>
        <mesh
          filename="../meshes/upperArm_link.STL" />
      </geometry>
      <material
        name="">
        <color
          rgba="0.75294 0.75294 0.75294 1" />
      </material>
    </visual>
    <collision>
      <origin
        xyz="0 0 0"
        rpy="0 0 0" />
      <geometry>
        <mesh
          filename="../meshes/upperArm_link.STL" />
      </geometry>
    </collision>
  </link>
  <joint
    name="upperArm_pitch"
    type="revolute">
    <origin
      xyz="0 0 0"
      rpy="0 0 0" />
    <parent
      link="shoulder_link" />
    <child
      link="upperArm_link" />
    <axis
      xyz="0 1 0" />
    <limit
      lower="0"
      upper="3.14"
      effort="0"
      velocity="0" />
  </joint>
  <link
    name="foreArm_link">
    <inertial>
      <origin
        xyz="0.016257 0.002161 0.041839"
        rpy="0 0 0" />
      <mass
        value="0.16941" />
      <inertia
        ixx="0.00021126"
        ixy="-2.5493E-07"
        ixz="-1.0205E-08"
        iyy="0.00031247"
        iyz="3.9576E-06"
        izz="0.00028419" />
    </inertial>
    <visual>
      <origin
        xyz="0 0 0"
        rpy="0 0 0" />
      <geometry>
        <mesh
          filename="../meshes/foreArm_link.STL" />
      </geometry>
      <material
        name="">
        <color
          rgba="0.75294 0.75294 0.75294 1" />
      </material>
    </visual>
    <collision>
      <origin
        xyz="0 0 0"
        rpy="0 0 0" />
      <geometry>
        <mesh
          filename="../meshes/foreArm_link.STL" />
      </geometry>
    </collision>
  </link>
  <joint
    name="foreArm_pitch"
    type="revolute">
    <origin
      xyz="-0.22125 -0.0020573 0"
      rpy="0 0 0" />
    <parent
      link="upperArm_link" />
    <child
      link="foreArm_link" />
    <axis
      xyz="0 -1 0" />
    <limit
      lower="0"
      upper="3.14"
      effort="0"
      velocity="0" />
  </joint>
</robot>